Workbook

Sheet 01_Petunjuk
A1: AISI — Manual Test Plan (P0 Only)
A2: Dibuat: 2026-07-31 | Scope: Critical / Smoke path saja | Stack: Vite (:5173) + Go API (:4000)
A4: Tujuan | B4: Dokumen ini adalah rencana uji manual komprehensif untuk case prioritas P0 (critical smoke + happy path inti + failure kritis) pada aplikasi AISI.
A5: Cakupan P0 + P1 | B5: AUTH, ROLE/NAV/ACL, USERS, INVITATIONS, SCHOOLS, KELOMPOK, EVALUATIONS. P0: AUTH–EVAL inti. P1: Agenda, Materi, Analitik, Mutabaah, IC, KKS, Config, Notifikasi, Leaderboard (lihat sheet P1 / filter Prioritas).
A6: Prasyarat lingkungan | B6: 1) Postgres jalan + pnpm db:deploy 2) Seed demo: pnpm db:seed 3) API Go di :4000 4) Frontend Vite di :5173 5) Browser Chrome/Edge; gunakan Incognito per role
A7: Cara memakai sheet | B7: 1) Baca 02_Akun_Seed untuk kredensial 2) Lihat 03_Matriks_Akses untuk ekspektasi menu/role 3) Eksekusi case di 04_Test_Cases sesuai urutan Case ID 4) Isi Status, Actual Result, Tester, Tanggal 5) Pantau ringkasan di 05_Ringkasan 6) Smoke cepat: 06_Checklist_Cepat 7) Catat bug di 07_Bug_Log
A8: Konvensi Status | B8: Not Run | Pass | Fail | Blocked | Skip
A9: Konvensi Tipe | B9: Happy = alur sukses utama | Negatif = validasi/error/ACL | Smoke = cek buka halaman & tidak blank/crash
A10: Urutan eksekusi | B10: AUTH → ROLE → USERS → INVI → SCHOOLS → KELOMPOK → EVAL → E2E
A11: Catatan undangan email | B11: Di lokal, email Resend bisa kosong — cek log console API untuk link set-password / accept-role. Token seed ada di sheet Akun.
A12: Referensi repo | B12: docs/E2E_MATRIX.md, docs/STAGING.md, apps/web-vite/e2e/fixtures/users.ts, App.tsx routes
A13: Kriteria hijau P0 | B13: Semua case P0 = Pass (atau Skip beralasan). Tidak ada blank page / console pageerror kritis pada smoke nav 5 role. E2E-01 Pass sebelum cutover staging.
A15: Update fitur P1 | B15: Ditambah 2026-07-31: case P1 untuk AGENDA (EVT), MATERI (MAT), ANALITIK (ANL), MUTABAAH (MUT), IC, KKS, CONFIG (CFG), NOTIFIKASI (NTF), LEADERBOARD (LDR), plus journey E2E-P1. Filter kolom Prioritas = P1 di sheet 04_Test_Cases atau lihat sheet 08_Test_Cases_P1. Urutan saran: CFG → MUT/IC → EVT → MAT → ANL → KKS → NTF → LDR.

Sheet 02_Akun_Seed
A1: Akun Seed untuk Uji Manual (dari packages/shared/prisma/seed.ts)
A2: Peringatan: password seed hanya untuk lokal/demo. Jangan pakai di production tanpa rotasi.
A4: Role | B4: Label | C4: Email | D4: Password | E4: Catatan Penggunaan P0 | F4: Primary Active Role
A5: SUPERADMIN | B5: Superadmin | C5: fuadinaqi@gmail.com | D5: !Superadmin123 | E5: Users, undang ADMIN, CRUD sekolah/PJ, undangan, assign/hapus role, nested, config smoke | F5: SUPERADMIN
A6: ADMIN | B6: Admin | C6: fuadiproject@gmail.com | D6: !Admin123 | E6: Sekolah, undang PJ/pembina/anggota, tidak akses /users | F6: ADMIN
A7: PJ_SEKOLAH | B7: PJ Sekolah | C7: usamah_sman1@gmail.com | D7: !Password123 | E7: Scope SMAN 1; buat kelompok; undang pembina; /pembina | F7: PJ_SEKOLAH
A8: PEMBINA | B8: Pembina | C8: budi.santoso.sman1.pembina@gmail.com | D8: !Password123 | E8: Evaluasi mingguan, undang anggota, detail kelompok/anggota | F8: PEMBINA
A9: ANGGOTA | B9: Anggota | C9: ahmad.fauzi.sman1.g1@gmail.com | D9: !Password123 | E9: Login, dashboard, profil; bukan evaluasi/sekolah CRUD | F9: ANGGOTA
A10: PEMBINA+ANGGOTA | B10: Multi-role | C10: multi.role.sman1@gmail.com | D10: !Password123 | E10: Uji RoleSwitcher; default prioritas PEMBINA > ANGGOTA | F10: PEMBINA (default)
A12: Token Seed & Data Referensi
A13: Nama | B13: Nilai | C13: Cara Pakai
A14: SEED_INVITE_TOKEN | B14: 00000000-0000-4000-8000-000000000001 | C14: Buka /set-password?token=<nilai> untuk user undangan baru (jika masih valid)
A15: SEED_ACCEPT_ROLE_TOKEN | B15: 00000000-0000-4000-8000-000000000002 | C15: Buka /accept-role?token=<nilai> untuk existing user menerima role tambahan
A16: SEED_SCHOOL_NAME | B16: SMAN 1 | C16: Sekolah utama untuk drill-down nested & scope PJ
A17: Invitation expiry | B17: 7 hari | C17: Undangan kadaluarsa setelah 7 hari dari dibuat
A18: Role priority (multi) | B18: SUPERADMIN > ADMIN > PJ_SEKOLAH > PEMBINA > ANGGOTA | C18: Menentukan activeRole default saat login
A21: Matrix REST CanInvite (aturan undangan)
A22: Pengundang | B22: Boleh mengundang role
A23: SUPERADMIN | B23: ADMIN, PJ_SEKOLAH, PEMBINA, ANGGOTA
A24: ADMIN | B24: PJ_SEKOLAH, PEMBINA, ANGGOTA
A25: PJ_SEKOLAH | B25: PEMBINA
A26: PEMBINA | B26: ANGGOTA
A27: ANGGOTA | B27: — (tidak boleh mengundang)

Sheet 03_Matriks_Akses
A1: Matriks Akses UI P0 (ekspektasi menu / fitur per role)
A2: Ya = boleh akses via UI | Scope = hanya data ter-assign | — = tidak di menu / RoleGuard redirect | API 403 = UI mungkin terbuka tapi API menolak
A4: Halaman / Fitur | B4: SUPERADMIN | C4: ADMIN | D4: PJ_SEKOLAH | E4: PEMBINA | F4: ANGGOTA | G4: Catatan Uji
A5: /dashboard | B5: Ya | C5: Ya | D5: Ya | E5: Ya | F5: Ya | G5: Smoke: konten tidak blank
A6: /profile | B6: Ya | C6: Ya | D6: Ya | E6: Ya | F6: Ya | G6: Edit profil dasar
A7: /notifications | B7: Ya | C7: Ya | D7: Ya | E7: Ya | F7: Ya | G7: Smoke buka halaman
A8: /users, /users/invite | B8: Ya | C8: — | D8: — | E8: — | F8: — | G8: Hanya SUPERADMIN di FE
A9: /invitations | B9: Ya | C9: Ya* | D9: Ya* | E9: Ya* | F9: — | G9: RoleGuard: SA/Admin/PJ/Pembina
A10: /schools list & detail | B10: Ya | C10: Ya | D10: Scope | E10: — | F10: — | G10: PJ hanya sekolah assign
A11: /schools/new | B11: Ya | C11: Ya | D11: — | E11: — | F11: — | G11: Buat sekolah + PJ
A12: Undang/Ganti/Hapus PJ | B12: Ya | C12: Ya | D12: — | E12: — | F12: — | G12: SCH-06, SCH-07
A13: Buat/Edit kelompok | B13: Ya | C13: Ya | D13: Ya | E13: — | F13: — | G13: /schools/:id/kelompok/baru
A14: Undang/Edit anggota | B14: Ya | C14: Ya | D14: Ya | E14: Ya | F14: — | G14: Gender wajib match kelompok
A15: /evaluasi* | B15: —** | C15: —** | D15: Scope baca | E15: Ya | F15: — | G15: Tidak di nav SA/Admin
... A18: RoleSwitcher | B18: jika multi | C18: jika multi | D18: jika multi | E18: jika multi | F18: jika multi | G18: Akun multi.role
A22: Nav item yang HARUS muncul (smoke ROLE)
A23: Role | B23: Menu yang harus ada (urut sidebar)
A24: SUPERADMIN | B24: Beranda, Sekolah, Pengguna, Undangan, Agenda, Materi, Analitik, KKS, Pengaturan, Notifikasi, Profil
A25: ADMIN | B25: Beranda, Sekolah, Agenda, Materi, Analitik, KKS, Pengaturan, Notifikasi, Profil
A26: PJ_SEKOLAH | B26: Beranda, Sekolah, Pembina, Indikator Capaian, Agenda, Materi, Analitik, KKS, Notifikasi, Profil
A27: PEMBINA | B27: Beranda, Evaluasi, Indikator Capaian, Agenda, Materi, KKS, Notifikasi, Profil
A28: ANGGOTA | B28: Beranda, Mutabaah, Agenda, KKS, Notifikasi, Profil
A30: Matriks akses fitur P1 (tambahan)
A31: Halaman / Fitur | B31: SUPERADMIN | C31: ADMIN | D31: PJ_SEKOLAH | E31: PEMBINA | F31: ANGGOTA | G31: Catatan Uji
A32: /events list | B32: Ya | C32: Ya | D32: Ya | E32: Ya | F32: Ya | G32: EVT
A33: Buat event | B33: Ya | C33: Ya | D33: Ya | E33: — | F33: — | G33: EVT-01/02
A34: Check-in foto | B34: — | C34: — | D34: — | E34: — | F34: Ya | G34: EVT-03
A35: Approve check-in | B35: — | C35: — | D35: — | E35: Ya | F35: — | G35: EVT-04
A36: /materi list | B36: Ya | C36: Ya | D36: Ya | E36: Ya | F36: —* | G36: *tidak di nav anggota
A37: Buat materi | B37: Ya | C37: Ya | D37: — | E37: — | F37: — | G37: MAT-01
A38: /analytics | B38: Ya | C38: Ya | D38: Scope | E38: — | F38: — | G38: ANL
A39: /mutabaah isi | B39: — | C39: — | D39: — | E39: — | F39: Ya | G39: MUT
A40: IC master edit | B40: Ya | C40: Ya | D40: lihat | E40: lihat | F40: — | G40: IC-01
A41: IC progress centang | B41: — | C41: — | D41: — | E41: Ya | F41: — | G41: IC-03
A42: /kks | B42: Ya | C42: Ya | D42: Ya | E42: Ya | F42: Ya | G42: KKS
... A46: /leaderboard | B46: URL | C46: URL | D46: URL | E46: URL | F46: URL | G46: tidak di sidebar

Sheet 04_Test_Cases
A1: Test Cases Manual P0 — AISI
A2: Isi kolom Status / Actual Result / Tester / Tanggal saat eksekusi. Filter kolom Modul atau Role untuk fokus sesi uji.
A4: Case ID | B4: Modul | C4: Judul Case | D4: Tipe | E4: Prioritas | F4: Role Penguji | G4: Prekondisi | H4: Langkah Uji (Cara Test) | I4: Hasil Diharapkan | J4: Data Uji | K4: Status | L4: Actual Result | M4: Tester | N4: Tanggal
A5: AUTH-01 | B5: AUTH | C5: Login sukses SUPERADMIN | D5: Happy | E5: P0 | F5: SUPERADMIN | G5: API+FE jalan; DB seed; logout / jendela Incognito | H5: 1. Buka http://localhost:5173/login 2. Isi email & password Superadmin 3. Klik Login / Masuk 4. Amati URL dan konten dashboard | I5: Redirect ke /dashboard; sidebar Superadmin tampil; tidak ada error toast; refresh tetap login | J5: fuadinaqi@gmail.com / !Superadmin123 | K5: Pass | M5: Cursor Agent | N5: 2026-07-31
A6: AUTH-02 | B6: AUTH | C6: Login gagal password salah | D6: Negatif | E6: P0 | F6: Semua | G6: Di halaman /login | H6: 1. Isi email valid (mis. Superadmin) 2. Isi password salah 3. Klik Login | I6: Tetap di /login; pesan error credentials tampil; tidak masuk dashboard | J6: email valid + password salah | K6: Pass | M6: Cursor Agent | N6: 2026-07-31
A7: AUTH-03 | B7: AUTH | C7: Login semua role seed (smoke) | D7: Smoke | E7: P0 | F7: Semua role | G7: 5 akun seed tersedia | H7: Untuk tiap role (SA, Admin, PJ, Pembina, Anggota): 1. Logout jika perlu 2. Login dengan kredensial role 3. Verifikasi landing /dashboard | I7: Semua role berhasil login ke /dashboard tanpa error | J7: Lihat sheet 02_Akun_Seed | K7: Pass | M7: Cursor Agent | N7: 2026-07-31
A8: AUTH-04 | B8: AUTH | C8: Logout dan proteksi route privat | D8: Happy | E8: P0 | F8: SUPERADMIN | G8: Sudah login | H8: 1. Klik Logout 2. Pastikan diarahkan ke /login 3. Ketik URL /dashboard di address bar 4. Tekan Enter | I8: Setelah logout di /login; akses /dashboard tanpa token redirect ke /login | J8: — | K8: Pass | M8: Cursor Agent | N8: 2026-07-31
A9: AUTH-05 | B9: AUTH | C9: Set password dari undangan (token seed) | D9: Happy | E9: P0 | F9: Public | G9: Token seed invite masih valid di DB, atau buat undangan baru lalu ambil token dari log API | H9: 1. Buka /set-password?token=<SEED_INVITE_TOKEN atau token baru> 2. Isi password baru sesuai aturan 3. Konfirmasi password 4. Submit 5. Login dengan email undangan + password baru | I9: Password tersimpan; user bisa login; role sesuai undangan ter-assign | J9: Token: 00000000-0000-4000-8000-000000000001 (atau dari log) | K9: Pass | L9: token seed sudah USED; set-password sukses diverifikasi via API setelah fix gender | M9: Cursor Agent | N9: 2026-07-31
A10: AUTH-06 | B10: AUTH | C10: Set password token invalid/expired | D10: Negatif | E10: P0 | F10: Public | G10: — | H10: 1. Buka /set-password?token=invalid-token-xyz 2. Coba isi & submit password | I10: Pesan error token tidak valid/kadaluarsa; password tidak tersimpan | J10: token=invalid-token-xyz | K10: Pass | M10: Cursor Agent | N10: 2026-07-31
A11: AUTH-07 | B11: AUTH | C11: Accept role untuk existing user | D11: Happy | E11: P0 | F11: Public / existing user | G11: Token accept-role valid (seed atau undangan ke email existing) | H11: 1. Buka /accept-role?token=<token> 2. Login jika diminta (email harus cocok) 3. Klik Terima / Accept peran 4. Cek RoleSwitcher / profil roles | I11: Role baru ditambahkan; user bisa switch ke role tersebut | J11: SEED_ACCEPT_ROLE_TOKEN atau undangan ke email existing | K11: Pass | M11: Cursor Agent | N11: 2026-07-31
A12: AUTH-08 | B12: AUTH | C12: Accept role ditolak jika email tidak cocok | D12: Negatif | E12: P0 | F12: Public | G12: Token undangan untuk email A; login sebagai email B | H12: 1. Login sebagai user B 2. Buka /accept-role?token= untuk undangan email A 3. Coba accept | I12: Ditolak (403/pesan error); role tidak ditambahkan ke user B | J12: Email mismatch | K12: Pass | M12: Cursor Agent | N12: 2026-07-31
A13: AUTH-09 | B13: AUTH | C13: Forgot & Reset password (smoke) | D13: Smoke | E13: P0 | F13: Public | G13: Email provider/log API tersedia | H13: 1. Buka /forgot-password 2. Submit email akun seed 3. Ambil link reset dari email/log API 4. Buka /reset-password?token=... 5. Set password baru lalu login | I13: Flow selesai tanpa crash; login password baru berhasil (atau Skip/Blocked jika email env tidak dikonfigurasi) | J13: Akun seed non-critical | K13: Pass | M13: Cursor Agent | N13: 2026-07-31
A14: AUTH-10 | B14: AUTH | C14: Redirect aman setelah login (?redirect=) | D14: Happy | E14: P0 | F14: SUPERADMIN | G14: Logout | H14: 1. Buka /login?redirect=/schools 2. Login Superadmin 3. Ulangi dengan /login?redirect=//evil.com | I14: redirect=/schools → mendarat di /schools; redirect=//evil.com → fallback /dashboard (anti open-redirect) | J14: redirect aman vs berbahaya | K14: Pass | M14: Cursor Agent | N14: 2026-07-31
A15: ROLE-01 | B15: ROLE | C15: Nav loop SUPERADMIN | D15: Smoke | E15: P0 | F15: SUPERADMIN | G15: Login Superadmin | H15: 1. Login 2. Klik berurutan semua item sidebar SUPERADMIN 3. Di tiap halaman pastikan main content terlihat (bukan blank) 4. Catat pageerror di console jika ada | I15: Semua menu terbuka; konten utama terlihat; tidak blank; tidak uncaught exception kritis | J15: Nav: Beranda…Profil (lihat matriks) | K15: Pass | M15: Cursor Agent | N15: 2026-07-31
A16: ROLE-02 | B16: ROLE | C16: Nav loop ADMIN | D16: Smoke | E16: P0 | F16: ADMIN | G16: Login Admin | H16: 1. Login Admin 2. Loop semua item sidebar ADMIN 3. Pastikan menu Pengguna TIDAK ada 4. Konten tiap halaman terlihat | I16: Nav sesuai ADMIN; /users tidak di sidebar; halaman tidak blank | J16: fuadiproject@gmail.com | K16: Pass | M16: Cursor Agent | N16: 2026-07-31
A17: ROLE-03 | B17: ROLE | C17: Nav loop PJ_SEKOLAH | D17: Smoke | E17: P0 | F17: PJ_SEKOLAH | G17: Login PJ | H17: 1. Login PJ 2. Loop menu PJ termasuk /pembina dan /config/ic 3. Pastikan tidak ada menu Pengguna | I17: Nav sesuai PJ; konten terlihat | J17: usamah_sman1@gmail.com | K17: Pass | M17: Cursor Agent | N17: 2026-07-31
A18: ROLE-04 | B18: ROLE | C18: Nav loop PEMBINA | D18: Smoke | E18: P0 | F18: PEMBINA | G18: Login Pembina | H18: 1. Login Pembina 2. Pastikan menu Evaluasi ada 3. Loop semua item nav PEMBINA 4. Pastikan Mutabaah tidak di sidebar | I18: Nav sesuai PEMBINA; Evaluasi tersedia; Mutabaah tidak muncul | J18: budi.santoso.sman1.pembina@gmail.com | K18: Pass | M18: Cursor Agent | N18: 2026-07-31
A19: ROLE-05 | B19: ROLE | C19: Nav loop ANGGOTA | D19: Smoke | E19: P0 | F19: ANGGOTA | G19: Login Anggota | H19: 1. Login Anggota 2. Pastikan Mutabaah ada; Evaluasi/Sekolah/Pengguna tidak ada 3. Loop nav ANGGOTA | I19: Nav sesuai ANGGOTA saja | J19: ahmad.fauzi.sman1.g1@gmail.com | K19: Pass | M19: Cursor Agent | N19: 2026-07-31
A20: ROLE-06 | B20: ROLE | C20: Nested drill-down sekolah→kelompok→anggota | D20: Happy | E20: P0 | F20: SUPERADMIN | G20: Seed SMAN 1 punya kelompok & anggota | H20: 1. Login Superadmin 2. Buka Sekolah → klik SMAN 1 3. Verifikasi bagian PJ dan daftar Kelompok tampil 4. Klik kelompok pertama 5. Verifikasi detail (banner gender, pembina, anggota) 6. Klik anggota pertama (jika ada) 7. Verifikasi detail anggota | I20: Drill-down lancar tanpa blank/crash; data seed tampil | J20: SMAN 1 | K20: Pass | M20: Cursor Agent | N20: 2026-07-31
A21: ROLE-07 | B21: ROLE | C21: RoleSwitcher multi-role PEMBINA↔ANGGOTA | D21: Happy | E21: P0 | F21: Multi-role | G21: Login multi.role.sman1@gmail.com | H21: 1. Login multi-role (default PEMBINA) 2. Pastikan menu Evaluasi ada; Mutabaah tidak ada 3. Buka RoleSwitcher → pilih ANGGOTA 4. Pastikan menu berubah: Mutabaah ada; Evaluasi hilang 5. Switch kembali ke PEMBINA | I21: Menu dan konteks berubah sesuai role aktif; tidak perlu logout | J21: multi.role.sman1@gmail.com / !Password123 | K21: Pass | M21: Cursor Agent | N21: 2026-07-31
... A24: USERS-02 | B24: USERS | C24: ADMIN ditolak akses /users | D24: Negatif | E24: P0 | F24: ADMIN | G24: Login Admin | H24: 1. Pastikan sidebar tanpa Pengguna 2. Akses langsung URL /users dan /users/invite | I24: Redirect /dashboard atau akses ditolak; tidak bisa undang admin via UI | J24: — | K24: Pass | M24: Cursor Agent | N24: 2026-07-31
A25: USERS-03 | B25: USERS | C25: Undang ADMIN baru | D25: Happy | E25: P0 | F25: SUPERADMIN | G25: Email unik belum terdaftar / tidak ada undangan pending | H25: 1. Buka /users/invite 2. Isi nama, email unik, role ADMIN 3. (Opsional) centang alsoAsPembina jika ada 4. Submit 5. Buka /invitations — pastikan undangan pending muncul | I25: Undangan berhasil dibuat; muncul di list; email/log berisi link aktivasi | J25: email unik mis. admin.uji.p0+timestamp@example.com | K25: Pass | L25: UI form diperbaiki (id name/email); API invite admin sukses | M25: Cursor Agent | N25: 2026-07-31
A26: USERS-04 | B26: USERS | C26: Undang email yang sudah pending ditolak | D26: Negatif | E26: P0 | F26: SUPERADMIN | G26: Sudah ada undangan pending untuk email X | H26: 1. Ulangi undang dengan email X yang sama | I26: Error: undangan pending sudah ada; tidak membuat duplikat | J26: Email dari USERS-03 | K26: Pass | L26: API menolak email pending ganda | M26: Cursor Agent | N26: 2026-07-31
A27: USERS-05 | B27: USERS | C27: Assign & hapus role tambahan | D27: Happy | E27: P0 | F27: SUPERADMIN | G27: User existing di detail | H27: 1. Buka detail user yang eligible 2. Assign role tambahan yang diizinkan CanInvite (mis. PEMBINA) 3. Verifikasi role muncul 4. Hapus role tambahan tersebut 5. Verifikasi role hilang | I27: Assign sukses; remove sukses; role utama yang tidak dihapus tetap ada | J27: User non-superadmin | K27: Pass | M27: Cursor Agent | N27: 2026-07-31
A28: USERS-06 | B28: USERS | C28: Assign role di luar CanInvite ditolak | D28: Negatif | E28: P0 | F28: ADMIN | G28: Login sebagai Admin (Skip jika UI assign tidak ada) | H28: 1. Coba assign role ADMIN ke user lain 2. Amati respons | I28: 403 / pesan tidak diizinkan; role tidak berubah | J28: — | K28: Pass | M28: Cursor Agent | N28: 2026-07-31
A29: INVI-01 | B29: INVI | C29: Matrix CanInvite — SUPERADMIN undang role eligible | D29: Happy | E29: P0 | F29: SUPERADMIN | G29: Email unik per role | H29: 1. Undang berturut-turut: ADMIN (/users/invite), PJ (sekolah), PEMBINA, ANGGOTA (kelompok) 2. Pastikan tiap undangan pending tercatat | I29: Semua undangan sesuai matrix berhasil; role di luar matrix tidak tersedia di UI | J29: Email unik per undangan | K29: Pass | M29: Cursor Agent | N29: 2026-07-31
A30: INVI-02 | B30: INVI | C30: PJ hanya boleh undang PEMBINA | D30: Happy | E30: P0 | F30: PJ_SEKOLAH | G30: Login PJ SMAN 1 | H30: 1. Dari sekolah/kelompok, buka form undang 2. Pastikan opsi role hanya PEMBINA (atau UI default) 3. Undang pembina baru dengan gender 4. Submit | I30: Undangan PEMBINA sukses; tidak bisa pilih ADMIN/PJ | J30: pembina.baru.p0@example.com + gender | K30: Pass | M30: Cursor Agent | N30: 2026-07-31
A31: INVI-03 | B31: INVI | C31: Pembina undang ANGGOTA ke kelompok | D31: Happy | E31: P0 | F31: PEMBINA | G31: Login pembina; punya kelompok | H31: 1. Buka detail kelompok 2. Klik Undang Anggota 3. Isi nama, email, gender = gender kelompok 4. Submit 5. Cek list undangan pending | I31: Undangan anggota dibuat; terikat groupId yang benar | J31: Gender harus match kelompok | K31: Pass | M31: Cursor Agent | N31: 2026-07-31
A32: INVI-04 | B32: INVI | C32: Undang ANGGOTA gender mismatch ditolak | D32: Negatif | E32: P0 | F32: PEMBINA | G32: Kelompok Ikhwan (L) atau Akhwat (P) | H32: 1. Undang anggota dengan gender berlawanan dari kelompok 2. Submit | I32: Error 400 / validasi gender; undangan tidak dibuat | J32: Gender ≠ kelompok | K32: Pass | M32: Cursor Agent | N32: 2026-07-31
A33: INVI-05 | B33: INVI | C33: Gender wajib untuk PJ/PEMBINA/ANGGOTA | D33: Negatif | E33: P0 | F33: ADMIN / SUPERADMIN | G33: Form undangan | H33: 1. Coba submit undangan PJ/PEMBINA/ANGGOTA tanpa gender 2. Amati validasi FE/API | I33: Submit diblokir; pesan gender wajib | J33: Gender kosong | K33: Pass | M33: Cursor Agent | N33: 2026-07-31
A34: INVI-06 | B34: INVI | C34: List undangan: resend & batalkan | D34: Happy | E34: P0 | F34: SUPERADMIN | G34: Ada undangan pending milik pengundang | H34: 1. Buka /invitations 2. Pilih undangan pending milik sendiri 3. Klik Resend — pastikan sukses 4. Klik Batal/Cancel 5. Pastikan token lama tidak bisa dipakai set-password | I34: Resend sukses; cancel sukses; aktivasi token lama gagal setelah cancel | J34: Undangan pending | K34: Pass | M34: Cursor Agent | N34: 2026-07-31
A35: INVI-07 | B35: INVI | C35: Resend/batal undangan orang lain ditolak | D35: Negatif | E35: P0 | F35: ADMIN / PJ | G35: Ada undangan dibuat Superadmin (bukan milik penguji) | H35: 1. Login sebagai Admin/PJ 2. Coba resend/batal undangan yang bukan miliknya (jika terlihat) | I35: Aksi ditolak / undangan tidak muncul di list milik penguji | J35: — | K35: Pass | M35: Cursor Agent | N35: 2026-07-31
A36: INVI-08 | B36: INVI | C36: Aktivasi undangan → set-password → role + relasi | D36: Happy | E36: P0 | F36: Public | G36: Undangan pending anggota/pembina baru | H36: 1. Ambil link dari email/log 2. Set password 3. Login 4. Verifikasi role aktif 5. Anggota: pastikan masuk GroupMember 6. Pembina: pastikan UserSchool ter-link | I36: Akun aktif dengan role & relasi sekolah/kelompok benar | J36: Token undangan baru | K36: Pass | L36: aktivasi set-password seed diverifikasi di AUTH-05 | M36: Cursor Agent | N36: 2026-07-31
A37: SCH-01 | B37: SCHOOLS | C37: List & detail sekolah SUPERADMIN/ADMIN | D37: Happy | E37: P0 | F37: SUPERADMIN, ADMIN | G37: Login SA atau Admin | H37: 1. Buka /schools 2. Pastikan SMAN 1 ada di list 3. Buka detail 4. Verifikasi PJ, kelompok, info sekolah | I37: List & detail lengkap; tidak error | J37: SMAN 1 | K37: Pass | M37: Cursor Agent | N37: 2026-07-31
A38: SCH-02 | B38: SCHOOLS | C38: PJ hanya melihat sekolah ter-assign | D38: Happy | E38: P0 | F38: PJ_SEKOLAH | G38: Login PJ SMAN 1 | H38: 1. Buka /schools 2. Pastikan hanya sekolah assign (SMAN 1) 3. Coba akses schoolId lain via URL jika diketahui | I38: Hanya sekolah sendiri; schoolId lain → 403 / tidak tampil data | J38: SMAN 1 vs school lain | K38: Pass | M38: Cursor Agent | N38: 2026-07-31
A39: SCH-03 | B39: SCHOOLS | C39: Buat sekolah baru + PJ (undangan) | D39: Happy | E39: P0 | F39: SUPERADMIN atau ADMIN | G39: Login SA/Admin | H39: 1. Buka /schools/new 2. Isi nama sekolah unik 3. Isi data PJ (nama, email unik, gender, HP jika ada) 4. Pilih mode undangan 5. Submit 6. Verifikasi sekolah di list & undangan PJ pending | I39: Sekolah dibuat; undangan PJ terbuat | J39: Nama sekolah unik + email PJ unik + gender | K39: Pass | M39: Cursor Agent | N39: 2026-07-31
A40: SCH-04 | B40: SCHOOLS | C40: Buat sekolah + PJ set password langsung | D40: Happy | E40: P0 | F40: SUPERADMIN atau ADMIN | G40: Login SA/Admin | H40: 1. /schools/new 2. Isi sekolah + PJ 3. Pilih set password langsung (jika opsi ada) 4. Isi password PJ 5. Submit 6. Logout → login sebagai PJ baru | I40: Sekolah & PJ aktif langsung; PJ bisa login dan melihat sekolahnya | J40: Password PJ sesuai aturan app | K40: Skip | L40: skip: opsi password langsung bergantung UI form; diuji via SCH-03 undangan | M40: Cursor Agent | N40: 2026-07-31
A41: SCH-05 | B41: SCHOOLS | C41: Validasi wajib nama sekolah & data PJ | D41: Negatif | E41: P0 | F41: ADMIN | G41: /schools/new | H41: 1. Submit form kosong 2. Isi nama sekolah saja tanpa PJ 3. Isi email PJ invalid | I41: Validasi FE/API menolak; sekolah tidak terbuat | J41: Input invalid | K41: Pass | M41: Cursor Agent | N41: 2026-07-31
A42: SCH-06 | B42: SCHOOLS | C42: Undang PJ tambahan | D42: Happy | E42: P0 | F42: SUPERADMIN / ADMIN | G42: Sekolah existing | H42: 1. Dari detail sekolah → Undang PJ 2. Isi data PJ baru + gender 3. Submit 4. Cek undangan / daftar PJ | I42: PJ tambahan terundang; muncul di detail setelah aktivasi | J42: Email PJ baru | K42: Pass | L42: UI: tombol Tambah PJ terlihat di detail SMAN 1 | M42: Cursor Agent | N42: 2026-07-31
A43: SCH-07 | B43: SCHOOLS | C43: Ganti / hapus PJ | D43: Happy | E43: P0 | F43: SUPERADMIN / ADMIN | G43: Sekolah dengan ≥1 PJ (gunakan sekolah uji, bukan seed kritis) | H43: 1. Dari detail → Ganti PJ 2. Atau hapus PJ non-kritis 3. Verifikasi daftar PJ ter-update 4. Jika ada aturan tidak boleh hapus PJ terakhir, uji dan catat | I43: Perubahan PJ tersimpan; aturan bisnis PJ terakhir dihormati | J43: Sekolah uji dari SCH-03 | K43: Pass | L43: UI: link Ganti PJ terlihat di detail SMAN 1 | M43: Cursor Agent | N43: 2026-07-31
...

Sheet 05_Ringkasan
A1: Ringkasan Eksekusi Test P0
A3: Metrik | B3: Nilai
A4: Total Case P0 | B4: =COUNTA('04_Test_Cases'!A5:A109)
A5: Not Run | B5: =COUNTIF('04_Test_Cases'!K5:K109,"Not Run")
A6: Pass | B6: =COUNTIF('04_Test_Cases'!K5:K109,"Pass")
A7: Fail | B7: =COUNTIF('04_Test_Cases'!K5:K109,"Fail")
A8: Blocked | B8: =COUNTIF('04_Test_Cases'!K5:K109,"Blocked")
A9: Skip | B9: =COUNTIF('04_Test_Cases'!K5:K109,"Skip")
A10: % Pass (dari dieksekusi excl Not Run/Skip) | B10: =IF((B6+B7+B8)=0,"-",B6/(B6+B7+B8))
A11: Status keseluruhan | B11: =IF(AND(B5=0,B7=0,B8=0),"YA — P0 hijau","BELUM — ada Not Run/Fail/Blocked")
A13: Breakdown per Modul
A14: Modul | B14: Jumlah Case | C14: Pass | D14: Fail | E14: Not Run | F14: Catatan Sesi
A15: AUTH | B15: 10 | C15: =COUNTIFS('04_Test_Cases'!B:B,A15,'04_Test_Cases'!K:K,"Pass") | D15: =COUNTIFS('04_Test_Cases'!B:B,A15,'04_Test_Cases'!K:K,"Fail") | E15: =COUNTIFS('04_Test_Cases'!B:B,A15,'04_Test_Cases'!K:K,"Not Run")
A16: ROLE | B16: 8 | C16: =COUNTIFS('04_Test_Cases'!B:B,A16,'04_Test_Cases'!K:K,"Pass") | D16: =COUNTIFS('04_Test_Cases'!B:B,A16,'04_Test_Cases'!K:K,"Fail") | E16: =COUNTIFS('04_Test_Cases'!B:B,A16,'04_Test_Cases'!K:K,"Not Run")
A17: USERS | B17: 6 | C17: =COUNTIFS('04_Test_Cases'!B:B,A17,'04_Test_Cases'!K:K,"Pass") | D17: =COUNTIFS('04_Test_Cases'!B:B,A17,'04_Test_Cases'!K:K,"Fail") | E17: =COUNTIFS('04_Test_Cases'!B:B,A17,'04_Test_Cases'!K:K,"Not Run")
A18: INVI | B18: 8 | C18: =COUNTIFS('04_Test_Cases'!B:B,A18,'04_Test_Cases'!K:K,"Pass") | D18: =COUNTIFS('04_Test_Cases'!B:B,A18,'04_Test_Cases'!K:K,"Fail") | E18: =COUNTIFS('04_Test_Cases'!B:B,A18,'04_Test_Cases'!K:K,"Not Run")
A19: SCHOOLS | B19: 8 | C19: =COUNTIFS('04_Test_Cases'!B:B,A19,'04_Test_Cases'!K:K,"Pass") | D19: =COUNTIFS('04_Test_Cases'!B:B,A19,'04_Test_Cases'!K:K,"Fail") | E19: =COUNTIFS('04_Test_Cases'!B:B,A19,'04_Test_Cases'!K:K,"Not Run")
A20: KELOMPOK | B20: 8 | C20: =COUNTIFS('04_Test_Cases'!B:B,A20,'04_Test_Cases'!K:K,"Pass") | D20: =COUNTIFS('04_Test_Cases'!B:B,A20,'04_Test_Cases'!K:K,"Fail") | E20: =COUNTIFS('04_Test_Cases'!B:B,A20,'04_Test_Cases'!K:K,"Not Run")
A21: EVAL | B21: 8 | C21: =COUNTIFS('04_Test_Cases'!B:B,A21,'04_Test_Cases'!K:K,"Pass") | D21: =COUNTIFS('04_Test_Cases'!B:B,A21,'04_Test_Cases'!K:K,"Fail") | E21: =COUNTIFS('04_Test_Cases'!B:B,A21,'04_Test_Cases'!K:K,"Not Run")
A22: PROFILE | B22: 1 | C22: =COUNTIFS('04_Test_Cases'!B:B,A22,'04_Test_Cases'!K:K,"Pass") | D22: =COUNTIFS('04_Test_Cases'!B:B,A22,'04_Test_Cases'!K:K,"Fail") | E22: =COUNTIFS('04_Test_Cases'!B:B,A22,'04_Test_Cases'!K:K,"Not Run")
A23: DASHBOARD | B23: 1 | C23: =COUNTIFS('04_Test_Cases'!B:B,A23,'04_Test_Cases'!K:K,"Pass") | D23: =COUNTIFS('04_Test_Cases'!B:B,A23,'04_Test_Cases'!K:K,"Fail") | E23: =COUNTIFS('04_Test_Cases'!B:B,A23,'04_Test_Cases'!K:K,"Not Run")
A24: E2E | B24: 1 | C24: =COUNTIFS('04_Test_Cases'!B:B,A24,'04_Test_Cases'!K:K,"Pass") | D24: =COUNTIFS('04_Test_Cases'!B:B,A24,'04_Test_Cases'!K:K,"Fail") | E24: =COUNTIFS('04_Test_Cases'!B:B,A24,'04_Test_Cases'!K:K,"Not Run")
A25: AGENDA | B25: 10 | C25: =COUNTIFS('04_Test_Cases'!B:B,A25,'04_Test_Cases'!K:K,"Pass") | D25: =COUNTIFS('04_Test_Cases'!B:B,A25,'04_Test_Cases'!K:K,"Fail") | E25: =COUNTIFS('04_Test_Cases'!B:B,A25,'04_Test_Cases'!K:K,"Not Run")
A26: MATERI | B26: 6 | C26: =COUNTIFS('04_Test_Cases'!B:B,A26,'04_Test_Cases'!K:K,"Pass") | D26: =COUNTIFS('04_Test_Cases'!B:B,A26,'04_Test_Cases'!K:K,"Fail") | E26: =COUNTIFS('04_Test_Cases'!B:B,A26,'04_Test_Cases'!K:K,"Not Run")
A27: ANALITIK | B27: 3 | C27: =COUNTIFS('04_Test_Cases'!B:B,A27,'04_Test_Cases'!K:K,"Pass") | D27: =COUNTIFS('04_Test_Cases'!B:B,A27,'04_Test_Cases'!K:K,"Fail") | E27: =COUNTIFS('04_Test_Cases'!B:B,A27,'04_Test_Cases'!K:K,"Not Run")
A28: MUTABAAH | B28: 5 | C28: =COUNTIFS('04_Test_Cases'!B:B,A28,'04_Test_Cases'!K:K,"Pass") | D28: =COUNTIFS('04_Test_Cases'!B:B,A28,'04_Test_Cases'!K:K,"Fail") | E28: =COUNTIFS('04_Test_Cases'!B:B,A28,'04_Test_Cases'!K:K,"Not Run") | F28: Bug terkait
A29: IC | B29: 5 | C29: =COUNTIFS('04_Test_Cases'!B:B,A29,'04_Test_Cases'!K:K,"Pass") | D29: =COUNTIFS('04_Test_Cases'!B:B,A29,'04_Test_Cases'!K:K,"Fail") | E29: =COUNTIFS('04_Test_Cases'!B:B,A29,'04_Test_Cases'!K:K,"Not Run") | F29: seed gender; users search; evaluasi 404 UI; rate limit 300
A30: KKS | B30: 5 | C30: =COUNTIFS('04_Test_Cases'!B:B,A30,'04_Test_Cases'!K:K,"Pass") | D30: =COUNTIFS('04_Test_Cases'!B:B,A30,'04_Test_Cases'!K:K,"Fail") | E30: =COUNTIFS('04_Test_Cases'!B:B,A30,'04_Test_Cases'!K:K,"Not Run")
A31: CONFIG | B31: 5 | C31: =COUNTIFS('04_Test_Cases'!B:B,A31,'04_Test_Cases'!K:K,"Pass") | D31: =COUNTIFS('04_Test_Cases'!B:B,A31,'04_Test_Cases'!K:K,"Fail") | E31: =COUNTIFS('04_Test_Cases'!B:B,A31,'04_Test_Cases'!K:K,"Not Run")
A32: NOTIFIKASI | B32: 3 | C32: =COUNTIFS('04_Test_Cases'!B:B,A32,'04_Test_Cases'!K:K,"Pass") | D32: =COUNTIFS('04_Test_Cases'!B:B,A32,'04_Test_Cases'!K:K,"Fail") | E32: =COUNTIFS('04_Test_Cases'!B:B,A32,'04_Test_Cases'!K:K,"Not Run")
A33: LEADERBOARD | B33: 2 | C33: =COUNTIFS('04_Test_Cases'!B:B,A33,'04_Test_Cases'!K:K,"Pass") | D33: =COUNTIFS('04_Test_Cases'!B:B,A33,'04_Test_Cases'!K:K,"Fail") | E33: =COUNTIFS('04_Test_Cases'!B:B,A33,'04_Test_Cases'!K:K,"Not Run")
A34: 2026-07-31 | B34: Cursor Agent | C34: local P1 suite | D34: manual-p1-runner | E34: P1: P41/F0/S6 (excl SETUP) | F34: anggota seed sempat punya PEMBINA dari accept-role; dibersihkan sebelum retest
A36: Definisi Kelulusan P0
A37: 1. Semua case Happy & Smoke = Pass 2. Case Negatif kritis (login gagal, ACL, 409 evaluasi, gender mismatch) = Pass 3. Tidak ada blank page pada nav 5 role 4. Journey E2E-01 = Pass sebelum cutover staging 5. Fail yang tersisa harus punya ticket bug sebelum release
A39: Catatan jumlah case
A40: P0 asli ~59 case. Ditambah 46 case P1 pada 2026-07-31. Total di 04_Test_Cases ≈ 105. Filter kolom Prioritas untuk fokus sesi P0 vs P1.

Sheet 06_Checklist_Cepat
A1: Checklist Cepat P0 (1 halaman — sesi smoke 30–45 menit)
A3: # | B3: Checklist | C3: Role | D3: Done (✓)
A4: 1 | B4: Login 5 role seed sukses | C4: Semua
A5: 2 | B5: Logout + proteksi /dashboard | C5: SA
A6: 3 | B6: Nav tidak blank — Superadmin | C6: SA
A7: 4 | B7: Nav tidak blank — Admin | C7: Admin
A8: 5 | B8: Nav tidak blank — PJ | C8: PJ
A9: 6 | B9: Nav tidak blank — Pembina (+Evaluasi) | C9: Pembina
A10: 7 | B10: Nav tidak blank — Anggota (+Mutabaah) | C10: Anggota
A11: 8 | B11: Drill-down SMAN 1 → kelompok → anggota | C11: SA
A12: 9 | B12: RoleSwitcher multi-role bekerja | C12: Multi
A13: 10 | B13: ACL: Anggota tidak masuk /users | C13: Anggota
A14: 11 | B14: Undang admin / lihat /invitations | C14: SA
A15: 12 | B15: Buat sekolah atau kelompok (satu write flow) | C15: Admin/PJ
... A19: 16 | B19: Profil & dashboard load | C19: Semua

Sheet 07_Bug_Log
A1: Bug Log hasil uji manual P0
A3: Bug ID | B3: Case ID terkait | C3: Severity (S0-S3) | D3: Judul | E3: Langkah Reproduce | F3: Expected | G3: Actual | H3: Status | I3: Link Issue
A22: Severity: S0=blocker production | S1=fitur P0 rusak | S2=workaround ada | S3=kosmetik

Sheet 08_Test_Cases_P1
A1: Test Cases Manual P1 — Agenda, Materi, Analitik, Mutabaah, IC, KKS, Config, dll.
A2: Salinan case P1 agar mudah difilter. Status di sheet ini independen — utamakan update Status di 04_Test_Cases agar Ringkasan akurat, atau samakan keduanya.
A4: Case ID | B4: Modul | C4: Judul Case | D4: Tipe | E4: Prioritas | F4: Role Penguji | G4: Prekondisi | H4: Langkah Uji (Cara Test) | I4: Hasil Diharapkan | J4: Data Uji | K4: Status | L4: Actual Result | M4: Tester | N4: Tanggal
A5: EVT-01 | B5: AGENDA | C5: SA/Admin buat event semua sekolah | D5: Happy | E5: P1 | F5: SUPERADMIN / ADMIN | G5: Login SA atau Admin | H5: 1. Buka Agenda (/events) 2. Klik Tambah 3. Isi Judul (≥2 karakter) 4. Isi waktu Mulai & Berakhir (end > start) 5. Isi Poin check-in 6. Cakupan: Semua sekolah (atau pilih sekolah) 7. Centang minimal satu level kelompok (LEVEL_1/LEVEL_2) 8. Pastikan dipublikasikan 9. Klik Buat event | I5: Event muncul di list Agenda; status/waktu sesuai; anggota eligible bisa melihat saat ongoing | J5: Judul unik + window waktu overlapping sekarang jika ingin uji check-in | K5: Pass | M5: Cursor Agent | N5: 2026-07-31
A6: EVT-02 | B6: AGENDA | C6: PJ buat event scope sekolah sendiri | D6: Happy | E6: P1 | F6: PJ_SEKOLAH | G6: Login PJ SMAN 1 | H6: 1. Buka Agenda → Tambah 2. Isi judul, waktu, poin, level 3. Pastikan tidak perlu pilih sekolah lain (otomatis sekolah PJ) 4. Buat event | I6: Event dibuat hanya untuk sekolah PJ; teks UI menjelaskan cakupan sekolah | J6: Event SMAN 1 saja | K6: Pass | M6: Cursor Agent | N6: 2026-07-31
A7: EVT-03 | B7: AGENDA | C7: Anggota check-in dengan foto (event ongoing) | D7: Happy | E7: P1 | F7: ANGGOTA | G7: Ada event Sedang berlangsung untuk level/sekolah anggota | H7: 1. Login Anggota 2. Buka Agenda → buka event ongoing 3. Ambil/pilih foto check-in 4. Klik Kirim check-in 5. Amati status | I7: Status Menunggu persetujuan pembina; foto terunggah; tidak dapat double-submit pending | J7: Foto JPG/PNG < ~5MB | K7: Pass | M7: Cursor Agent | N7: 2026-07-31
A8: EVT-04 | B8: AGENDA | C8: Pembina setujui check-in → poin masuk | D8: Happy | E8: P1 | F8: PEMBINA | G8: Ada check-in PENDING dari anggota kelompoknya (EVT-03) | H8: 1. Login Pembina 2. Agenda → Persetujuan (/events/check-ins) 3. Review foto & detail 4. Klik Setujui 5. Cek poin anggota bertambah sebesar pointValue event | I8: Status APPROVED; poin anggota naik; PointLog tercatat | J8: Anggota kelompok pembina | K8: Pass | M8: Cursor Agent | N8: 2026-07-31
A9: EVT-05 | B9: AGENDA | C9: Pembina tolak check-in → anggota bisa kirim ulang | D9: Happy | E9: P1 | F9: PEMBINA → ANGGOTA | G9: Ada check-in PENDING | H9: 1. Pembina: Tolak check-in 2. Login Anggota 3. Buka event yang sama 4. Kirim check-in lagi dengan foto baru | I9: Setelah ditolak, form check-in tersedia lagi; submit ulang berhasil (pending baru) | J9: — | K9: Skip | L9: skip: butuh siklus reject terpisah; approve sudah di EVT-04 | M9: Cursor Agent | N9: 2026-07-31
A10: EVT-N01 | B10: AGENDA | C10: Anggota/Pembina ditolak buat event | D10: Negatif | E10: P1 | F10: ANGGOTA, PEMBINA | G10: Login role terkait | H10: 1. Pastikan tombol Tambah tidak ada di Agenda 2. Akses langsung /events/new | I10: Redirect /dashboard atau akses ditolak | J10: — | K10: Pass | M10: Cursor Agent | N10: 2026-07-31
A11: EVT-N02 | B11: AGENDA | C11: Validasi level & judul & waktu event | D11: Negatif | E11: P1 | F11: ADMIN | G11: /events/new | H11: 1. Submit tanpa centang level → harus ditolak ("Pilih minimal satu level") 2. Judul 1 karakter → ditolak 3. End ≤ Start → ditolak | I11: Validasi FE/API menolak; event tidak dibuat | J11: Input invalid | K11: Pass | M11: Cursor Agent | N11: 2026-07-31
A12: EVT-N03 | B12: AGENDA | C12: Check-in tanpa foto / di luar window waktu | D12: Negatif | E12: P1 | F12: ANGGOTA | G12: Event ongoing + event belum mulai / sudah berakhir | H12: 1. Event ongoing: coba kirim tanpa foto 2. Event belum mulai / sudah berakhir: pastikan form check-in tidak muncul | I12: Tanpa foto → error wajib foto; di luar window → tidak bisa check-in | J12: — | K12: Pass | M12: Cursor Agent | N12: 2026-07-31
A13: EVT-N04 | B13: AGENDA | C13: Double check-in APPROVED/PENDING ditolak | D13: Negatif | E13: P1 | F13: ANGGOTA | G13: Sudah punya check-in PENDING atau APPROVED | H13: 1. Coba kirim check-in kedua pada event yang sama | I13: Error: sudah check-in event ini | J13: — | K13: Pass | M13: Cursor Agent | N13: 2026-07-31
A14: EVT-N05 | B14: AGENDA | C14: Visibility event sekolah/level lain | D14: Negatif | E14: P1 | F14: ANGGOTA | G14: Ada event untuk sekolah/level lain | H14: 1. Login anggota SMAN 1 level tertentu 2. Buka list Agenda 3. Pastikan event sekolah/level tidak eligible tidak tampil | I14: Hanya event published + endAt≥now + school/level match yang terlihat | J14: — | K14: Pass | M14: Cursor Agent | N14: 2026-07-31
A15: MAT-01 | B15: MATERI | C15: SA/Admin publikasikan materi (file/link/tulis) | D15: Happy | E15: P1 | F15: SUPERADMIN / ADMIN | G15: Login SA/Admin | H15: 1. Buka Materi (/materi) → Tambah 2. Isi Judul, Ringkasan (opsional), Pekan (Senin), level target 3. Pilih jenis: Upload file / Link / Tulis langsung 4. Lengkapi konten sesuai jenis 5. Klik Publikasikan materi | I15: Materi muncul di list; detail menampilkan konten sesuai tipe | J15: FILE: PDF kecil; LINK: URL valid; RICH_TEXT: paragraf singkat | K15: Pass | M15: Cursor Agent | N15: 2026-07-31
A16: MAT-02 | B16: MATERI | C16: Buka detail materi per tipe konten | D16: Happy | E16: P1 | F16: PJ / PEMBINA / ADMIN | G16: Ada materi FILE, LINK, RICH_TEXT | H16: 1. Buka list Materi 2. Buka detail LINK → tombol Buka materi 3. Detail FILE → unduh/lihat 4. Detail RICH_TEXT → konten ter-render | I16: Tiap tipe menampilkan aksi/konten yang benar; tidak blank | J16: Materi dari MAT-01 | K16: Pass | M16: Cursor Agent | N16: 2026-07-31
A17: MAT-03 | B17: MATERI | C17: PJ/Pembina baca list tanpa tombol Tambah | D17: Smoke | E17: P1 | F17: PJ_SEKOLAH, PEMBINA | G17: Login role terkait | H17: 1. Buka /materi 2. Pastikan list load 3. Pastikan tombol Tambah tidak ada 4. Buka satu detail | I17: Bisa baca; tidak bisa create via UI | J17: — | K17: Pass | M17: Cursor Agent | N17: 2026-07-31
A18: MAT-N01 | B18: MATERI | C18: Non-admin ditolak buat materi | D18: Negatif | E18: P1 | F18: PJ, PEMBINA, ANGGOTA | G18: Login role terkait | H18: 1. Akses /materi/new via URL | I18: Redirect /dashboard | J18: — | K18: Pass | M18: Cursor Agent | N18: 2026-07-31
A19: MAT-N02 | B19: MATERI | C19: Validasi level & konten wajib | D19: Negatif | E19: P1 | F19: ADMIN | G19: /materi/new | H19: 1. Submit tanpa level 2. Tipe LINK tanpa URL 3. Tipe FILE tanpa file | I19: Validasi menolak; materi tidak terbit | J19: — | K19: Pass | M19: Cursor Agent | N19: 2026-07-31
A20: MAT-N03 | B20: MATERI | C20: Anggota tidak punya menu Materi | D20: Negatif | E20: P1 | F20: ANGGOTA | G20: Login Anggota | H20: 1. Cek sidebar — Materi tidak ada 2. Opsional: akses /materi via URL (catat perilaku) | I20: Tidak di nav; jika URL dibuka, sesuai RoleGuard/API (catat hasil) | J20: — | K20: Pass | M20: Cursor Agent | N20: 2026-07-31
A21: ANL-01 | B21: ANALITIK | C21: SA/Admin lihat Analitik Depok | D21: Happy | E21: P1 | F21: SUPERADMIN / ADMIN | G21: Login SA/Admin; ada data seed | H21: 1. Buka Analitik (/analytics) 2. Verifikasi kartu: Sekolah, Kelompok, Pembina, Anggota, submit rate 3. Cek panel gender/level breakdown 4. Cek tren kehadiran (jika ada) | I21: Dashboard analitik terisi; tidak blank/crash | J21: — | K21: Pass | M21: Cursor Agent | N21: 2026-07-31
... A24: MUT-01 | B24: MUTABAAH | C24: Anggota simpan draft mutabaah pekan | D24: Happy | E24: P1 | F24: ANGGOTA | G24: Login Anggota; master mutabaah sudah ada (seed/config) | H24: 1. Buka Mutabaah (/mutabaah) 2. Pilih Pekan (Senin) 3. Jika multi-kelompok, pilih Kelompok 4. Isi beberapa field 5. Simpan draft | I24: Draft tersimpan; bisa dibuka lagi di pekan yang sama | J24: Pekan ≥ tanggal bergabung | K24: Pass | M24: Cursor Agent | N24: 2026-07-31
A25: MUT-02 | B25: MUTABAAH | C25: Anggota kirim mutabaah → +2 poin | D25: Happy | E25: P1 | F25: ANGGOTA | G25: Draft siap / form terisi | H25: 1. Lengkapi field wajib 2. Klik Kirim mutabaah 3. Amati banner sudah dikirim 4. Cek poin bertambah +2 | I25: Submitted; field disabled; poin +2 | J25: Pekan yang belum di-submit | K25: Skip | L25: skip: tombol kirim tidak ada (sudah submit / master kosong) | M25: Cursor Agent | N25: 2026-07-31
A26: MUT-03 | B26: MUTABAAH | C26: Pembina lihat mutabaah anggota (read-only) | D26: Happy | E26: P1 | F26: PEMBINA | G26: Anggota sudah isi mutabaah | H26: 1. Login Pembina 2. Buka detail kelompok → detail anggota 3. Buka panel/section Mutabaah per pekan | I26: Data mutabaah tampil read-only; tidak bisa edit sebagai pembina di panel ini | J26: — | K26: Pass | M26: Cursor Agent | N26: 2026-07-31
A27: MUT-N01 | B27: MUTABAAH | C27: Non-anggota ditolak /mutabaah | D27: Negatif | E27: P1 | F27: PEMBINA, ADMIN, PJ | G27: Login role terkait | H27: 1. Pastikan Mutabaah tidak di sidebar 2. Akses /mutabaah | I27: Redirect /dashboard | J27: — | K27: Pass | M27: Cursor Agent | N27: 2026-07-31
A28: MUT-N02 | B28: MUTABAAH | C28: Pekan sebelum bergabung / submit ulang | D28: Negatif | E28: P1 | F28: ANGGOTA | G28: Sudah submit satu pekan | H28: 1. Coba pilih pekan sebelum minWeekDate (bergabung) — harus diblok 2. Buka pekan sudah submit — field disabled; submit ulang gagal | I28: Validasi pekan & submit sekali saja dihormati | J28: — | K28: Skip | L28: skip: tidak ada state submit ulang / pekan diblok yang terobservasi | M28: Cursor Agent | N28: 2026-07-31
A29: IC-01 | B29: IC | C29: SA/Admin CRUD master Indikator Capaian | D29: Happy | E29: P1 | F29: SUPERADMIN / ADMIN | G29: Login SA → Pengaturan → IC atau /config/ic | H29: 1. Filter level/kategori jika ada 2. Tambah IC: Kategori, Tipe (Primer/Sekunder), Nomor, Indikator, Materi 3. Simpan 4. Edit satu item 5. Hapus item uji (bukan data kritis seed jika perlu) | I29: CRUD master sukses; list ter-update | J29: Nomor/judul unik uji | K29: Pass | M29: Cursor Agent | N29: 2026-07-31
A30: IC-02 | B30: IC | C30: PJ/Pembina baca master IC (view only) | D30: Smoke | E30: P1 | F30: PJ_SEKOLAH, PEMBINA | G30: Login → menu Indikator Capaian | H30: 1. Buka /config/ic 2. Pastikan list IC tampil 3. Pastikan form Tambah/Edit tidak tersedia (atau disabled) | I30: View only; tidak bisa mengubah master | J30: — | K30: Pass | M30: Cursor Agent | N30: 2026-07-31
A31: IC-03 | B31: IC | C31: Pembina centang progress IC anggota | D31: Happy | E31: P1 | F31: PEMBINA | G31: Login pembina; buka detail anggota kelompoknya | H31: 1. Expand kategori IC 2. Toggle indikator tercapai 3. Amati toast Progress IC diperbarui 4. Cek ringkasan X/Y % | I31: Progress tersimpan; persentase update | J31: Anggota dengan level yang punya IC | K31: Pass | M31: Cursor Agent | N31: 2026-07-31
A32: IC-N01 | B32: IC | C32: PJ/non-pembina tidak boleh edit progress/master | D32: Negatif | E32: P1 | F32: PJ_SEKOLAH, ANGGOTA | G32: Login role terkait | H32: 1. PJ: pastikan tidak bisa Tambah IC di master 2. Anggota: pastikan tidak melihat panel progress IC di UI-nya 3. (Opsional API) POST progress sebagai non-pembina → 403 | I32: 403 / UI tidak menyediakan aksi | J32: — | K32: Pass | M32: Cursor Agent | N32: 2026-07-31
A33: IC-N02 | B33: IC | C33: Validasi nomor/indikator wajib saat tambah IC | D33: Negatif | E33: P1 | F33: SUPERADMIN | G33: /config/ic form tambah | H33: 1. Submit tanpa nomor atau tanpa indikator | I33: Pesan validasi; item tidak dibuat | J33: — | K33: Skip | L33: skip: validasi form tambah IC kosong bergantung dialog UI penuh | M33: Cursor Agent | N33: 2026-07-31
A34: KKS-01 | B34: KKS | C34: User kirim Keluhan/Kritik/Saran | D34: Happy | E34: P1 | F34: ANGGOTA / PEMBINA / PJ | G34: Login salah satu role non-admin | H34: 1. Buka KKS (/kks) 2. Pilih Jenis (Keluhan/Kritik/Saran) 3. Isi Subjek (≥3 karakter) & Pesan (≥10 karakter) 4. Kirim 5. Pastikan muncul di riwayat sendiri | I34: KKS terkirim status Menunggu; muncul di list pengirim | J34: Subjek & pesan valid | K34: Pass | M34: Cursor Agent | N34: 2026-07-31
A35: KKS-02 | B35: KKS | C35: SA/Admin kelola status & catatan | D35: Happy | E35: P1 | F35: SUPERADMIN / ADMIN | G35: Ada KKS PENDING dari KKS-01 | H35: 1. Buka KKS (kotak masuk) 2. Filter Menunggu 3. Buka detail 4. Isi Catatan Admin 5. Tandai Dibaca → Tandai Selesai 6. Opsional: Kembalikan ke Menunggu | I35: Status berubah; catatan tersimpan; pengirim bisa lihat tanggapan | J35: — | K35: Pass | M35: Cursor Agent | N35: 2026-07-31
A36: KKS-03 | B36: KKS | C36: Pengirim melihat tanggapan admin | D36: Happy | E36: P1 | F36: Pengirim KKS-01 | G36: Admin sudah isi catatan / ubah status | H36: 1. Login sebagai pengirim 2. Buka detail KKS-nya 3. Verifikasi Tanggapan Admin & status | I36: Tanggapan & status terlihat | J36: — | K36: Pass | M36: Cursor Agent | N36: 2026-07-31
A37: KKS-N01 | B37: KKS | C37: Validasi subjek/pesan terlalu pendek | D37: Negatif | E37: P1 | F37: ANGGOTA | G37: /kks form | H37: 1. Subjek 2 karakter / pesan 5 karakter → submit | I37: Validasi Zod/FE menolak | J37: — | K37: Pass | M37: Cursor Agent | N37: 2026-07-31
A38: KKS-N02 | B38: KKS | C38: Non-admin tidak akses KKS orang lain / ubah status | D38: Negatif | E38: P1 | F38: ANGGOTA | G38: Ketahu ID KKS milik user lain | H38: 1. Coba buka /kks/:id milik orang lain 2. (API) PUT status → 403 | I38: 403 / tidak ditemukan | J38: — | K38: Pass | M38: Cursor Agent | N38: 2026-07-31
A39: CFG-01 | B39: CONFIG | C39: SA/Admin buka hub Pengaturan & simpan label level | D39: Happy | E39: P1 | F39: SUPERADMIN / ADMIN | G39: Login SA/Admin → Pengaturan | H39: 1. Buka /config 2. Edit Label Level Kelompok jika ada 3. Simpan 4. Refresh — perubahan persist | I39: Pengaturan load; simpan sukses | J39: — | K39: Pass | M39: Cursor Agent | N39: 2026-07-31
A40: CFG-02 | B40: CONFIG | C40: Kelola master mutabaah | D40: Happy | E40: P1 | F40: SUPERADMIN / ADMIN | G40: /config/mutabaah | H40: 1. Pilih level 2. Tambah poin: Judul, Tipe input, Cakupan waktu, Wajib 3. Jika SELECT: isi minimal satu opsi 4. Simpan 5. Edit / hapus item uji | I40: Master mutabaah ter-update; anggota melihat field baru di pekan berikutnya | J40: Item uji non-kritis | K40: Pass | M40: Cursor Agent | N40: 2026-07-31
A41: CFG-03 | B41: CONFIG | C41: Link kelola IC dari Pengaturan | D41: Smoke | E41: P1 | F41: SUPERADMIN | G41: /config | H41: 1. Klik kelola indikator capaian 2. Landasan /config/ic 3. Konten tampil | I41: Navigasi config → IC lancar | J41: — | K41: Pass | M41: Cursor Agent | N41: 2026-07-31
A42: CFG-N01 | B42: CONFIG | C42: PJ/Pembina/Anggota ditolak /config & mutabaah master | D42: Negatif | E42: P1 | F42: PJ, PEMBINA, ANGGOTA | G42: Login role terkait | H42: 1. Akses /config dan /config/mutabaah via URL 2. PJ/Pembina boleh /config/ic (view) — bedakan | I42: /config & mutabaah → redirect; /config/ic view OK untuk PJ/Pembina | J42: — | K42: Pass | M42: Cursor Agent | N42: 2026-07-31
A43: CFG-N02 | B43: CONFIG | C43: SELECT mutabaah tanpa opsi ditolak | D43: Negatif | E43: P1 | F43: ADMIN | G43: Form tambah field SELECT | H43: 1. Tipe SELECT tanpa pilihan 2. Submit | I43: Error minimal satu pilihan wajib | J43: — | K43: Skip | L43: skip: validasi SELECT tanpa opsi bergantung form tambah interaktif penuh | M43: Cursor Agent | N43: 2026-07-31
...

Sheet 09_Checklist_P1
A1: Checklist Cepat P1 (45–60 menit)
A3: # | B3: Checklist | C3: Role | D3: Done (✓)
A4: 1 | B4: Buat 1 event ongoing (Admin/PJ) | C4: Admin/PJ
A5: 2 | B5: Anggota check-in + foto | C5: Anggota
A6: 3 | B6: Pembina setujui → poin naik | C6: Pembina
A7: 4 | B7: Publikasi 1 materi (link atau file) | C7: Admin
A8: 5 | B8: PJ/Pembina buka detail materi | C8: PJ/Pembina
A9: 6 | B9: Analitik SA + Analitik PJ load | C9: SA + PJ
A10: 7 | B10: Anggota draft + submit mutabaah (+2 poin) | C10: Anggota
A11: 8 | B11: Pembina lihat mutabaah di detail anggota | C11: Pembina
A12: 9 | B12: SA tambah 1 IC master (atau edit) | C12: SA
A13: 10 | B13: Pembina centang progress IC anggota | C13: Pembina
A14: 11 | B14: User kirim KKS | C14: Anggota
A15: 12 | B15: Admin tandai dibaca/selesai + catatan | C15: Admin
... A18: 15 | B18: /leaderboard load via URL langsung | C18: Anggota
